Workbook

Sheet Articles
A1: Article ID | B1: Year | C1: Number of Authors | D1: Magazine | E1: Sector | F1: Quotations | G1: Copies Sold | H1: Cost
A2: ART8062 | B2: 2018 | C2: 1 | D2: Journal of Convention and Event Tourism | E2: Tourism | F2: 7 | G2: 25464 | H2: 12239
A3: ART7942 | B3: 2019 | C3: 1 | D3: Tourism Economics | E3: Tourism | F3: 3 | G3: 22158 | H3: 9461
A4: ART6879 | B4: 2016 | C4: 1 | D4: Tourism Management | E4: Tourism | F4: 9 | G4: 22767 | H4: 24325
A5: ART1326 | B5: 2019 | C5: 3 | D5: Journal of Urban Affairs | E5: Architecture | F5: 13 | G5: 32613 | H5: 0
A6: ART1121 | B6: 2020 | C6: 1 | D6: Tourism Management | E6: Tourism | F6: 13 | H6: 0
A7: ART9483 | B7: 2016 | C7: 2 | D7: Journal of Sport & Tourism | E7: Tourism | F7: 7 | G7: 34723 | H7: 0
A8: ART7405 | B8: 2020 | C8: 2 | D8: Journal of Sport & Tourism | E8: Tourism | F8: 4 | G8: 15137 | H8: 0
A9: ART9781 | B9: 2020 | C9: 2 | D9: Journal of Convention and Event Tourism | E9: Tourism | F9: 1 | G9: 36226 | H9: 8219
A10: ART7411 | B10: 2017 | C10: 2 | D10: Tourism Economics | E10: Tourism | F10: 4 | G10: 13456 | H10: 24098
A11: ART9588 | B11: 2018 | C11: 1 | D11: Journal of Convention and Event Tourism | E11: Tourism | F11: 3 | G11: 13082 | H11: 8991
A12: ART2865 | B12: 2021 | C12: 3 | D12: Annals of Tourism Research | E12: Tourism | F12: 14 | G12: 28807 | H12: 12357
A13: ART6658 | B13: 2019 | C13: 3 | D13: Journal of Travel Research | E13: Tourism | F13: 1 | G13: 39496 | H13: 29793
A14: ART7727 | B14: 2018 | C14: 1 | D14: Tourism Economics | E14: Tourism | F14: 10 | H14: 0
A15: ART6748 | B15: 2024 | C15: 1 | D15: Journal of Hospitality Management | E15: Tourism | F15: 14 | G15: 26600 | H15: 21699
A16: ART7662 | B16: 2016 | C16: 2 | D16: Event Management | E16: Marketing | F16: 4 | G16: 11384 | H16: 25351
A17: ART9180 | B17: 2024 | C17: 1 | D17: Tourism Management | E17: Tourism | F17: 14 | G17: 25299 | H17: 28069
A18: ART1747 | B18: 2024 | C18: 3 | D18: Tourism Management | E18: Tourism | F18: 10 | H18: 0
A19: ART2693 | B19: 2018 | C19: 1 | D19: Tourism etc | E19: Tourism | F19: 9 | G19: 28041 | H19: 17326
A20: ART2940 | B20: 2024 | C20: 2 | D20: Tourism Management | E20: Tourism | F20: 12 | G20: 23957 | H20: 0
A21: ART8985 | B21: 2022 | C21: 1 | D21: Public Transport International | E21: Tourism | F21: 15 | G21: 23265 | H21: 3044
A22: ART9898 | B22: 2023 | C22: 1 | D22: Tourism Management | E22: Tourism | F22: 1 | G22: 24265 | H22: 23555
A23: ART7327 | B23: 2021 | C23: 1 | D23: Tourism Management | E23: Tourism | F23: 13 | G23: 25671 | H23: 21929
A24: ART5720 | B24: 2019 | C24: 2 | D24: Tourism Economics | E24: Tourism | F24: 4 | G24: 16716 | H24: 0
A25: ART3191 | B25: 2024 | C25: 2 | D25: Tourism Economics | E25: Tourism | F25: 10 | G25: 28141 | H25: 19958
A26: ART1729 | B26: 2015 | C26: 3 | D26: Tourism Management | E26: Tourism | F26: 3 | G26: 23195 | H26: 20908
A27: ART6572 | B27: 2016 | C27: 3 | D27: Journal of Travel and Tourism Marketing | E27: Tourism | F27: 11 | G27: 14259 | H27: 17948
A28: ART7732 | B28: 2018 | C28: 3 | D28: Tourism Economics | E28: Tourism | F28: 14 | G28: 12038 | H28: 15587
A29: ART7134 | B29: 2021 | C29: 2 | D29: Annals of Tourism Research | E29: Tourism | F29: 4 | G29: 10148 | H29: 4021
A30: ART7496 | B30: 2018 | C30: 2 | D30: Tourism Economics | E30: Tourism | F30: 11 | G30: 21365 | H30: 20115
A31: ART9335 | B31: 2016 | C31: 2 | D31: Tourism Management | E31: Tourism | F31: 3 | H31: 0
A32: ART5871 | B32: 2021 | C32: 2 | D32: Tourism Management | E32: Tourism | F32: 14 | G32: 21056 | H32: 19474
A33: ART5574 | B33: 2017 | C33: 3 | D33: Journal of Sport & Tourism | E33: Tourism | F33: 8 | G33: 14536 | H33: 5511
A34: ART9360 | B34: 2024 | C34: 2 | D34: Tourism Analysis | E34: Tourism | F34: 7 | G34: 16834 | H34: 0
A35: ART2457 | B35: 2015 | C35: 2 | D35: Tourism Economics | E35: Tourism | F35: 13 | G35: 31748 | H35: 25121
A36: ART2070 | B36: 2023 | C36: 3 | D36: Annals of Tourism Research | E36: Tourism | F36: 13 | H36: 0
A37: ART3110 | B37: 2022 | C37: 3 | D37: Tourism Review International | E37: Tourism | F37: 4 | G37: 27605 | H37: 21035
A38: ART6415 | B38: 2017 | C38: 1 | D38: Canadian Geographer | E38: Geography | F38: 3 | G38: 27610 | H38: 25673
A39: ART1511 | B39: 2020 | C39: 1 | D39: Journal of Sport & Tourism | E39: Tourism | F39: 4 | G39: 13552 | H39: 0
A40: ART6544 | B40: 2016 | C40: 2 | D40: Current Issues in Tourism | E40: Tourism | F40: 9 | G40: 12793 | H40: 0
...

Sheet Press campaign
B2: Year | C2: The total number of articles with more than 5 quotations, for each year | D2: Total cost on magazines with more than 25,000 copies sold | E2: The average quotations on articles with cost less than or equal to 10,000 $
B3: 2015 | C3: =COUNTIFS(Articles!$F$2:$F$306,">5",Articles!$B$2:$B$306,$B3) -> 8 | D3: =SUMIFS(Articles!$H$2:$H$306,Articles!$G$2:$G$306,">25000",Articles!$B$2:$B$306,$B3) -> 194476 | E3: =AVERAGEIFS(Articles!$F$2:$F$306,Articles!$H$2:$H$306, "<=10000", Articles!$B$2:$B$306, 'Press campaign'!$B3) -> 5.8333333
B4: 2016 | C4: =COUNTIFS(Articles!$F$2:$F$306,">5",Articles!$B$2:$B$306,$B4) -> 21 | D4: =SUMIFS(Articles!$H$2:$H$306,Articles!$G$2:$G$306,">25000",Articles!$B$2:$B$306,$B4) -> 148879 | E4: =AVERAGEIFS(Articles!$F$2:$F$306,Articles!$H$2:$H$306, "<=10000", Articles!$B$2:$B$306, 'Press campaign'!$B4) -> 9.25
B5: 2017 | C5: =COUNTIFS(Articles!$F$2:$F$306,">5",Articles!$B$2:$B$306,$B5) -> 17 | D5: =SUMIFS(Articles!$H$2:$H$306,Articles!$G$2:$G$306,">25000",Articles!$B$2:$B$306,$B5) -> 112539 | E5: =AVERAGEIFS(Articles!$F$2:$F$306,Articles!$H$2:$H$306, "<=10000", Articles!$B$2:$B$306, 'Press campaign'!$B5) -> 9.0909091
B6: 2018 | C6: =COUNTIFS(Articles!$F$2:$F$306,">5",Articles!$B$2:$B$306,$B6) -> 28 | D6: =SUMIFS(Articles!$H$2:$H$306,Articles!$G$2:$G$306,">25000",Articles!$B$2:$B$306,$B6) -> 116459 | E6: =AVERAGEIFS(Articles!$F$2:$F$306,Articles!$H$2:$H$306, "<=10000", Articles!$B$2:$B$306, 'Press campaign'!$B6) -> 7.7058824
B7: 2019 | C7: =COUNTIFS(Articles!$F$2:$F$306,">5",Articles!$B$2:$B$306,$B7) -> 19 | D7: =SUMIFS(Articles!$H$2:$H$306,Articles!$G$2:$G$306,">25000",Articles!$B$2:$B$306,$B7) -> 158303 | E7: =AVERAGEIFS(Articles!$F$2:$F$306,Articles!$H$2:$H$306, "<=10000", Articles!$B$2:$B$306, 'Press campaign'!$B7) -> 7.7222222
B8: 2020 | C8: =COUNTIFS(Articles!$F$2:$F$306,">5",Articles!$B$2:$B$306,$B8) -> 15 | D8: =SUMIFS(Articles!$H$2:$H$306,Articles!$G$2:$G$306,">25000",Articles!$B$2:$B$306,$B8) -> 191485 | E8: =AVERAGEIFS(Articles!$F$2:$F$306,Articles!$H$2:$H$306, "<=10000", Articles!$B$2:$B$306, 'Press campaign'!$B8) -> 7.9230769
B9: 2021 | C9: =COUNTIFS(Articles!$F$2:$F$306,">5",Articles!$B$2:$B$306,$B9) -> 24 | D9: =SUMIFS(Articles!$H$2:$H$306,Articles!$G$2:$G$306,">25000",Articles!$B$2:$B$306,$B9) -> 184953 | E9: =AVERAGEIFS(Articles!$F$2:$F$306,Articles!$H$2:$H$306, "<=10000", Articles!$B$2:$B$306, 'Press campaign'!$B9) -> 7.5714286
B10: 2022 | C10: =COUNTIFS(Articles!$F$2:$F$306,">5",Articles!$B$2:$B$306,$B10) -> 21 | D10: =SUMIFS(Articles!$H$2:$H$306,Articles!$G$2:$G$306,">25000",Articles!$B$2:$B$306,$B10) -> 239419 | E10: =AVERAGEIFS(Articles!$F$2:$F$306,Articles!$H$2:$H$306, "<=10000", Articles!$B$2:$B$306, 'Press campaign'!$B10) -> 5.8
B11: 2023 | C11: =COUNTIFS(Articles!$F$2:$F$306,">5",Articles!$B$2:$B$306,$B11) -> 24 | D11: =SUMIFS(Articles!$H$2:$H$306,Articles!$G$2:$G$306,">25000",Articles!$B$2:$B$306,$B11) -> 252942 | E11: =AVERAGEIFS(Articles!$F$2:$F$306,Articles!$H$2:$H$306, "<=10000", Articles!$B$2:$B$306, 'Press campaign'!$B11) -> 9
B12: 2024 | C12: =COUNTIFS(Articles!$F$2:$F$306,">5",Articles!$B$2:$B$306,$B12) -> 27 | D12: =SUMIFS(Articles!$H$2:$H$306,Articles!$G$2:$G$306,">25000",Articles!$B$2:$B$306,$B12) -> 169674 | E12: =AVERAGEIFS(Articles!$F$2:$F$306,Articles!$H$2:$H$306, "<=10000", Articles!$B$2:$B$306, 'Press campaign'!$B12) -> 9.5263158
