Workbook

Sheet Case development
B2: Lesson 8 - Case 2
G3: My personal notes:
B4: To solve the case we need to:
B5: 1. | C5: In the new Hours for shipping column, use IF, ISTEXT and TODAY functions to calculate and how many hours passed between the sale date and time and shipping date and time, for each sale
B6: 2. | C6: In the new column Shipping management use the IF function and operation between dates to show, for each sale: - The text string “Excellent handling” if the shipment started in 48 hours or less - An empty cell if the shipment started in 48 to 96 hours - The text string “Bad handling” if the shipment started in 96 hours or more
B7: 3. | C7: In thenew Day check column use IF and WEEKDAY functions to show, for each sale, the text string “Weekend sale” if the sale was on a Sunday or on a Saturday, or an empty cell in all other cases
B8: 4. | C8: Use conditional formatting to apply a format to the cells of the Revenue field so that the cells corresponding to sales made after 1/1/2025 and with a revenue greater than or equal to 500 euros are automatically highlighted with a fill color of your choice
B9: 5. | C9: Use conditional formatting to apply a format to the cells of the Product field so that the cells corresponding to sales made between 10:00 AM (included) and 12:00 PM (not included) are automatically highlighted with a fill color of your choice
B10: 6. | C10: In the new Analysis worksheet use the SUMIFS fuction to calculate the total revenues for each category, considering only the sales carried out between 1/10/2025 and 1/20/2025 (both inclusive), . Then sort the categories, in the Analysis worksheet, in ascending order.

Sheet Stationery
A1: Sale date and time | B1: Item | C1: Category | D1: Supplier | E1: Shipment date and time | F1: Revenue | G1: Days for shipping | H1: Shipping management | I1: Day check
A2: 45694.241 | B2: Micro scotch | C2: Scotch | D2: Atemlos | E2: 45698.425 | F2: 88.71 | G2: =IF(ISTEXT(E2),TODAY(),E2)-A2 -> 4.1840329 | H2: =IF(G2*24<=48,"Excellent handling",IF(G2*24>=96,"Bad handling","")) -> Bad handling | I2: =IF(OR(WEEKDAY(A2)=1,WEEKDAY(A2)=7),"Weekend sale","")
A3: 45679.007 | B3: Large Commercial Envelope | C3: Commercial envelope | D3: Michels | E3: 45681.595 | F3: 499.26 | G3: =IF(ISTEXT(E3),TODAY(),E3)-A3 -> 2.5879333 | H3: =IF(G3*24<=48,"Excellent handling",IF(G3*24>=96,"Bad handling","")) | I3: =IF(OR(WEEKDAY(A3)=1,WEEKDAY(A3)=7),"Weekend sale","")
A4: 45666.231 | B4: Holed transparent folder | C4: Transparent folder | D4: Marins | E4: 45670.377 | F4: 317.45 | G4: =IF(ISTEXT(E4),TODAY(),E4)-A4 -> 4.1468907 | H4: =IF(G4*24<=48,"Excellent handling",IF(G4*24>=96,"Bad handling","")) -> Bad handling | I4: =IF(OR(WEEKDAY(A4)=1,WEEKDAY(A4)=7),"Weekend sale","")
A5: 45634.197 | B5: Maxi Blocknotes | C5: Blocknotes | D5: Juppers | E5: 45637.854 | F5: 168.33 | G5: =IF(ISTEXT(E5),TODAY(),E5)-A5 -> 3.6562379 | H5: =IF(G5*24<=48,"Excellent handling",IF(G5*24>=96,"Bad handling","")) | I5: =IF(OR(WEEKDAY(A5)=1,WEEKDAY(A5)=7),"Weekend sale","") -> Weekend sale
A6: 45632.443 | B6: Maxi-ballpoint pen | C6: Pen | D6: Juppers | E6: Not shipped | F6: 500.76 | G6: =IF(ISTEXT(E6),TODAY(),E6)-A6 -> 422.55668 | H6: =IF(G6*24<=48,"Excellent handling",IF(G6*24>=96,"Bad handling","")) -> Bad handling | I6: =IF(OR(WEEKDAY(A6)=1,WEEKDAY(A6)=7),"Weekend sale","")
A7: 45666.311 | B7: Maxi-ballpoint pen | C7: Pen | D7: Juppers | E7: 45668.708 | F7: 378.66 | G7: =IF(ISTEXT(E7),TODAY(),E7)-A7 -> 2.3970802 | H7: =IF(G7*24<=48,"Excellent handling",IF(G7*24>=96,"Bad handling","")) | I7: =IF(OR(WEEKDAY(A7)=1,WEEKDAY(A7)=7),"Weekend sale","")
A8: 45658.437 | B8: Tight Commercial Envelope | C8: Commercial envelope | D8: Juppers | E8: 45661.426 | F8: 790.44 | G8: =IF(ISTEXT(E8),TODAY(),E8)-A8 -> 2.9890147 | H8: =IF(G8*24<=48,"Excellent handling",IF(G8*24>=96,"Bad handling","")) | I8: =IF(OR(WEEKDAY(A8)=1,WEEKDAY(A8)=7),"Weekend sale","")
A9: 45653.185 | B9: Micro-Ballpoint pen | C9: Pen | D9: Jovines | E9: 45655.069 | F9: 546.05 | G9: =IF(ISTEXT(E9),TODAY(),E9)-A9 -> 1.883998 | H9: =IF(G9*24<=48,"Excellent handling",IF(G9*24>=96,"Bad handling","")) -> Excellent handling | I9: =IF(OR(WEEKDAY(A9)=1,WEEKDAY(A9)=7),"Weekend sale","")
A10: 45647.889 | B10: Med File Folder | C10: File folder | D10: Marins | E10: 45649.305 | F10: 291.65 | G10: =IF(ISTEXT(E10),TODAY(),E10)-A10 -> 1.415347 | H10: =IF(G10*24<=48,"Excellent handling",IF(G10*24>=96,"Bad handling","")) -> Excellent handling | I10: =IF(OR(WEEKDAY(A10)=1,WEEKDAY(A10)=7),"Weekend sale","") -> Weekend sale
A11: 45669.633 | B11: Small Commercial Envelope | C11: Commercial envelope | D11: Juppers | E11: 45673.76 | F11: 352.77 | G11: =IF(ISTEXT(E11),TODAY(),E11)-A11 -> 4.1275974 | H11: =IF(G11*24<=48,"Excellent handling",IF(G11*24>=96,"Bad handling","")) -> Bad handling | I11: =IF(OR(WEEKDAY(A11)=1,WEEKDAY(A11)=7),"Weekend sale","") -> Weekend sale
A12: 45680.738 | B12: Micro-Ballpoint pen | C12: Pen | D12: Jovines | E12: 45683.649 | F12: 464.22 | G12: =IF(ISTEXT(E12),TODAY(),E12)-A12 -> 2.9106914 | H12: =IF(G12*24<=48,"Excellent handling",IF(G12*24>=96,"Bad handling","")) | I12: =IF(OR(WEEKDAY(A12)=1,WEEKDAY(A12)=7),"Weekend sale","")
A13: 45661.006 | B13: Maxi scotch | C13: Scotch | D13: Joy | E13: 45663.884 | F13: 494.87 | G13: =IF(ISTEXT(E13),TODAY(),E13)-A13 -> 2.8783275 | H13: =IF(G13*24<=48,"Excellent handling",IF(G13*24>=96,"Bad handling","")) | I13: =IF(OR(WEEKDAY(A13)=1,WEEKDAY(A13)=7),"Weekend sale","") -> Weekend sale
A14: 45651.331 | B14: Maxi-ballpoint pen | C14: Pen | D14: Juppers | E14: See order notes | F14: 568.46 | G14: =IF(ISTEXT(E14),TODAY(),E14)-A14 -> 403.66859 | H14: =IF(G14*24<=48,"Excellent handling",IF(G14*24>=96,"Bad handling","")) -> Bad handling | I14: =IF(OR(WEEKDAY(A14)=1,WEEKDAY(A14)=7),"Weekend sale","")
A15: 45644.617 | B15: White Blocknotes | C15: Blocknotes | D15: Atemlos | E15: 45647.281 | F15: 512.26 | G15: =IF(ISTEXT(E15),TODAY(),E15)-A15 -> 2.6639742 | H15: =IF(G15*24<=48,"Excellent handling",IF(G15*24>=96,"Bad handling","")) | I15: =IF(OR(WEEKDAY(A15)=1,WEEKDAY(A15)=7),"Weekend sale","")
A16: 45693.893 | B16: DeLuxe Pencil sharpener | C16: Pencil Sharpener | D16: World Office Supplier | E16: 45694.614 | F16: 511.42 | G16: =IF(ISTEXT(E16),TODAY(),E16)-A16 -> 0.72130603 | H16: =IF(G16*24<=48,"Excellent handling",IF(G16*24>=96,"Bad handling","")) -> Excellent handling | I16: =IF(OR(WEEKDAY(A16)=1,WEEKDAY(A16)=7),"Weekend sale","")
A17: 45682.64 | B17: Pencil with rubber | C17: Pencil | D17: Marins | E17: 45686.466 | F17: 613.21 | G17: =IF(ISTEXT(E17),TODAY(),E17)-A17 -> 3.8256762 | H17: =IF(G17*24<=48,"Excellent handling",IF(G17*24>=96,"Bad handling","")) | I17: =IF(OR(WEEKDAY(A17)=1,WEEKDAY(A17)=7),"Weekend sale","") -> Weekend sale
A18: 45684.345 | B18: Med Blocknotes | C18: Blocknotes | D18: Jovines | E18: 45688.038 | F18: 196.42 | G18: =IF(ISTEXT(E18),TODAY(),E18)-A18 -> 3.6927804 | H18: =IF(G18*24<=48,"Excellent handling",IF(G18*24>=96,"Bad handling","")) | I18: =IF(OR(WEEKDAY(A18)=1,WEEKDAY(A18)=7),"Weekend sale","")
A19: 45663.609 | B19: Transparent tape | C19: Scotch | D19: Tuscanian | E19: 45666.903 | F19: 627.66 | G19: =IF(ISTEXT(E19),TODAY(),E19)-A19 -> 3.2943704 | H19: =IF(G19*24<=48,"Excellent handling",IF(G19*24>=96,"Bad handling","")) | I19: =IF(OR(WEEKDAY(A19)=1,WEEKDAY(A19)=7),"Weekend sale","")
A20: 45627.369 | B20: Holed transparent folder | C20: Transparent folder | D20: Marins | E20: 45627.469 | F20: 606.25 | G20: =IF(ISTEXT(E20),TODAY(),E20)-A20 -> 0.10003324 | H20: =IF(G20*24<=48,"Excellent handling",IF(G20*24>=96,"Bad handling","")) -> Excellent handling | I20: =IF(OR(WEEKDAY(A20)=1,WEEKDAY(A20)=7),"Weekend sale","") -> Weekend sale
A21: 45652.901 | B21: Tight Commercial Envelope | C21: Commercial envelope | D21: Juppers | E21: 45653.706 | F21: 558.38 | G21: =IF(ISTEXT(E21),TODAY(),E21)-A21 -> 0.80499687 | H21: =IF(G21*24<=48,"Excellent handling",IF(G21*24>=96,"Bad handling","")) -> Excellent handling | I21: =IF(OR(WEEKDAY(A21)=1,WEEKDAY(A21)=7),"Weekend sale","")
A22: 45662.878 | B22: Soft-Pencil Rubber | C22: Rubber | D22: Tuscanian | E22: 45665.759 | F22: 687.35 | G22: =IF(ISTEXT(E22),TODAY(),E22)-A22 -> 2.881209 | H22: =IF(G22*24<=48,"Excellent handling",IF(G22*24>=96,"Bad handling","")) | I22: =IF(OR(WEEKDAY(A22)=1,WEEKDAY(A22)=7),"Weekend sale","") -> Weekend sale
A23: 45655.146 | B23: Hard-Pencil Rubber | C23: Rubber | D23: Jovines | E23: 45658.193 | F23: 148.22 | G23: =IF(ISTEXT(E23),TODAY(),E23)-A23 -> 3.0472305 | H23: =IF(G23*24<=48,"Excellent handling",IF(G23*24>=96,"Bad handling","")) | I23: =IF(OR(WEEKDAY(A23)=1,WEEKDAY(A23)=7),"Weekend sale","") -> Weekend sale
A24: 45643.453 | B24: Small Commercial Envelope | C24: Commercial envelope | D24: Juppers | E24: 45648.382 | F24: 560.09 | G24: =IF(ISTEXT(E24),TODAY(),E24)-A24 -> 4.9291612 | H24: =IF(G24*24<=48,"Excellent handling",IF(G24*24>=96,"Bad handling","")) -> Bad handling | I24: =IF(OR(WEEKDAY(A24)=1,WEEKDAY(A24)=7),"Weekend sale","")
A25: 45636.142 | B25: Med Blocknotes | C25: Blocknotes | D25: Jovines | E25: NA | F25: 500.61 | G25: =IF(ISTEXT(E25),TODAY(),E25)-A25 -> 418.85808 | H25: =IF(G25*24<=48,"Excellent handling",IF(G25*24>=96,"Bad handling","")) -> Bad handling | I25: =IF(OR(WEEKDAY(A25)=1,WEEKDAY(A25)=7),"Weekend sale","")
A26: 45638.35 | B26: Blue/Red Pencil | C26: Pencil | D26: Joy | E26: 45641.271 | F26: 128.93 | G26: =IF(ISTEXT(E26),TODAY(),E26)-A26 -> 2.9213096 | H26: =IF(G26*24<=48,"Excellent handling",IF(G26*24>=96,"Bad handling","")) | I26: =IF(OR(WEEKDAY(A26)=1,WEEKDAY(A26)=7),"Weekend sale","")
A27: 45628.456 | B27: Soft-Pencil Rubber | C27: Rubber | D27: Tuscanian | E27: 45629.523 | F27: 665 | G27: =IF(ISTEXT(E27),TODAY(),E27)-A27 -> 1.0670294 | H27: =IF(G27*24<=48,"Excellent handling",IF(G27*24>=96,"Bad handling","")) -> Excellent handling | I27: =IF(OR(WEEKDAY(A27)=1,WEEKDAY(A27)=7),"Weekend sale","")
A28: 45659.08 | B28: Tight Commercial Envelope | C28: Commercial envelope | D28: Juppers | E28: 45664.059 | F28: 532.01 | G28: =IF(ISTEXT(E28),TODAY(),E28)-A28 -> 4.9784341 | H28: =IF(G28*24<=48,"Excellent handling",IF(G28*24>=96,"Bad handling","")) -> Bad handling | I28: =IF(OR(WEEKDAY(A28)=1,WEEKDAY(A28)=7),"Weekend sale","")
A29: 45653.183 | B29: Med Blocknotes | C29: Blocknotes | D29: Jovines | E29: 45653.4 | F29: 563.13 | G29: =IF(ISTEXT(E29),TODAY(),E29)-A29 -> 0.21735986 | H29: =IF(G29*24<=48,"Excellent handling",IF(G29*24>=96,"Bad handling","")) -> Excellent handling | I29: =IF(OR(WEEKDAY(A29)=1,WEEKDAY(A29)=7),"Weekend sale","")
A30: 45629.149 | B30: Transparent tape | C30: Scotch | D30: Tuscanian | E30: 45631.565 | F30: 590.64 | G30: =IF(ISTEXT(E30),TODAY(),E30)-A30 -> 2.4159584 | H30: =IF(G30*24<=48,"Excellent handling",IF(G30*24>=96,"Bad handling","")) | I30: =IF(OR(WEEKDAY(A30)=1,WEEKDAY(A30)=7),"Weekend sale","")
A31: 45670.202 | B31: Blue/Red Pencil | C31: Pencil | D31: Joy | E31: 45672.877 | F31: 334.22 | G31: =IF(ISTEXT(E31),TODAY(),E31)-A31 -> 2.6741112 | H31: =IF(G31*24<=48,"Excellent handling",IF(G31*24>=96,"Bad handling","")) | I31: =IF(OR(WEEKDAY(A31)=1,WEEKDAY(A31)=7),"Weekend sale","")
A32: 45640.174 | B32: 01-Refill pencil | C32: Pencil | D32: Marins | E32: 45641.698 | F32: 323.36 | G32: =IF(ISTEXT(E32),TODAY(),E32)-A32 -> 1.5242036 | H32: =IF(G32*24<=48,"Excellent handling",IF(G32*24>=96,"Bad handling","")) -> Excellent handling | I32: =IF(OR(WEEKDAY(A32)=1,WEEKDAY(A32)=7),"Weekend sale","") -> Weekend sale
A33: 45676.836 | B33: Refill HB Pencil | C33: Pencil Refill | D33: World Office Supplier | E33: 45678.838 | F33: 466.87 | G33: =IF(ISTEXT(E33),TODAY(),E33)-A33 -> 2.001994 | H33: =IF(G33*24<=48,"Excellent handling",IF(G33*24>=96,"Bad handling","")) | I33: =IF(OR(WEEKDAY(A33)=1,WEEKDAY(A33)=7),"Weekend sale","") -> Weekend sale
A34: 45666.395 | B34: 01-Refill pencil | C34: Pencil | D34: Marins | E34: 45668.181 | F34: 130.75 | G34: =IF(ISTEXT(E34),TODAY(),E34)-A34 -> 1.7856999 | H34: =IF(G34*24<=48,"Excellent handling",IF(G34*24>=96,"Bad handling","")) -> Excellent handling | I34: =IF(OR(WEEKDAY(A34)=1,WEEKDAY(A34)=7),"Weekend sale","")
A35: 45687.332 | B35: Mini File Folder | C35: File folder | D35: Brice | E35: 45687.647 | F35: 791.14 | G35: =IF(ISTEXT(E35),TODAY(),E35)-A35 -> 0.31543807 | H35: =IF(G35*24<=48,"Excellent handling",IF(G35*24>=96,"Bad handling","")) -> Excellent handling | I35: =IF(OR(WEEKDAY(A35)=1,WEEKDAY(A35)=7),"Weekend sale","")
A36: 45692.936 | B36: B Pencil | C36: Pencil | D36: Jovines | E36: Not shipped | F36: 769.01 | G36: =IF(ISTEXT(E36),TODAY(),E36)-A36 -> 362.06351 | H36: =IF(G36*24<=48,"Excellent handling",IF(G36*24>=96,"Bad handling","")) -> Bad handling | I36: =IF(OR(WEEKDAY(A36)=1,WEEKDAY(A36)=7),"Weekend sale","")
A37: 45647.024 | B37: Soft-Pencil Rubber | C37: Rubber | D37: Tuscanian | E37: 45650.033 | F37: 339.52 | G37: =IF(ISTEXT(E37),TODAY(),E37)-A37 -> 3.0089697 | H37: =IF(G37*24<=48,"Excellent handling",IF(G37*24>=96,"Bad handling","")) | I37: =IF(OR(WEEKDAY(A37)=1,WEEKDAY(A37)=7),"Weekend sale","") -> Weekend sale
A38: 45692.313 | B38: Midi-ballpoint pen | C38: Pen | D38: World Office Supplier | E38: 45694.335 | F38: 323.25 | G38: =IF(ISTEXT(E38),TODAY(),E38)-A38 -> 2.0216326 | H38: =IF(G38*24<=48,"Excellent handling",IF(G38*24>=96,"Bad handling","")) | I38: =IF(OR(WEEKDAY(A38)=1,WEEKDAY(A38)=7),"Weekend sale","")
A39: 45655.74 | B39: Double-sided tape | C39: Scotch | D39: Michels | E39: 45659.767 | F39: 804.95 | G39: =IF(ISTEXT(E39),TODAY(),E39)-A39 -> 4.0274674 | H39: =IF(G39*24<=48,"Excellent handling",IF(G39*24>=96,"Bad handling","")) -> Bad handling | I39: =IF(OR(WEEKDAY(A39)=1,WEEKDAY(A39)=7),"Weekend sale","") -> Weekend sale
A40: 45696.086 | B40: Med File Folder | C40: File folder | D40: Marins | E40: 45701.482 | F40: 111.19 | G40: =IF(ISTEXT(E40),TODAY(),E40)-A40 -> 5.3953988 | H40: =IF(G40*24<=48,"Excellent handling",IF(G40*24>=96,"Bad handling","")) -> Bad handling | I40: =IF(OR(WEEKDAY(A40)=1,WEEKDAY(A40)=7),"Weekend sale","") -> Weekend sale
...

Sheet Analysis
A1: Category | B1: Total revenues 10-20 Jan
A2: Blocknotes | B2: =SUMIFS(Stationery!F$2:F$630,Stationery!C$2:C$630,A2,Stationery!A$2:A$630,">=1/10/2025",Stationery!A$2:A$630,"<=1/20/2025") -> 0
A3: Commercial envelope | B3: =SUMIFS(Stationery!F$2:F$630,Stationery!C$2:C$630,A3,Stationery!A$2:A$630,">=1/10/2025",Stationery!A$2:A$630,"<=1/20/2025") -> 0
A4: File folder | B4: =SUMIFS(Stationery!F$2:F$630,Stationery!C$2:C$630,A4,Stationery!A$2:A$630,">=1/10/2025",Stationery!A$2:A$630,"<=1/20/2025") -> 0
A5: Pen | B5: =SUMIFS(Stationery!F$2:F$630,Stationery!C$2:C$630,A5,Stationery!A$2:A$630,">=1/10/2025",Stationery!A$2:A$630,"<=1/20/2025") -> 0
A6: Pencil | B6: =SUMIFS(Stationery!F$2:F$630,Stationery!C$2:C$630,A6,Stationery!A$2:A$630,">=1/10/2025",Stationery!A$2:A$630,"<=1/20/2025") -> 0
A7: Pencil Refill | B7: =SUMIFS(Stationery!F$2:F$630,Stationery!C$2:C$630,A7,Stationery!A$2:A$630,">=1/10/2025",Stationery!A$2:A$630,"<=1/20/2025") -> 0
A8: Pencil Sharpener | B8: =SUMIFS(Stationery!F$2:F$630,Stationery!C$2:C$630,A8,Stationery!A$2:A$630,">=1/10/2025",Stationery!A$2:A$630,"<=1/20/2025") -> 0
A9: Rubber | B9: =SUMIFS(Stationery!F$2:F$630,Stationery!C$2:C$630,A9,Stationery!A$2:A$630,">=1/10/2025",Stationery!A$2:A$630,"<=1/20/2025") -> 0
A10: Scotch | B10: =SUMIFS(Stationery!F$2:F$630,Stationery!C$2:C$630,A10,Stationery!A$2:A$630,">=1/10/2025",Stationery!A$2:A$630,"<=1/20/2025") -> 0
A11: Transparent folder | B11: =SUMIFS(Stationery!F$2:F$630,Stationery!C$2:C$630,A11,Stationery!A$2:A$630,">=1/10/2025",Stationery!A$2:A$630,"<=1/20/2025") -> 0
